Workbook

Sheet Setup
B1: Travel Estimate & Expense — User Testing Workbook
B2: Math is shown as live formulas on each scenario tab. You verify the app against these numbers by hand; the Result cells only compare what you type.
B4: SETTINGS (blue = edit)
B5: Fee multiplier (travel_settings.fee_multiplier) | C5: 1.1274 | D5: Applied to every ODC line except per diem meals and EWW. Confirm the Supervisor review screen shows "Fee Multiplier Used: 1.1274x" before you start.
B6: Dollar tolerance for PASS | C6: 0.01 | D6: Cents. A value within this of the expected figure counts as PASS.
B7: App build under test (commit) | C7: a3249e3 | D7: Update if the app is redeployed during testing.
B8: Tester name | D8: Add initials to every Event Name you type (see rule below).
B9: Test date
B10: Browser / device
B12: HOW TO USE
B13: 1. Steps tab | C13: Run-sheet | D13: Go scenario by scenario. Do the step, check what it says, set the Status. One person runs one scenario at a time.
B14: 2. Scenario tabs (S1-S8) | C14: Inputs + math | D14: Type the blue inputs exactly. Read the math rows. Then fill the yellow Actual cells in the Screen Checkpoints; Result turns PASS/FAIL.
B15: 3. Emails tab | C15: Count + verify | D15: Log every email that arrives. The summary at the top compares expected vs received per scenario.
B16: 4. Controls tab | C16: Coverage | D16: Shows every control and which scenarios exercise it. A GAP means no scenario touches it.
B17: 5. Watch List tab | C17: Suspected issues | D17: Hypotheses from reading the code. Confirm or clear each during the run.
B18: 6. Defects tab | C18: Log | D18: Anything wrong that is not already on the Watch List.
B20: EVENT NAME RULE (so emails can be matched)
B21: Type exactly | C21: S2 Customer Site Visit - JD | D21: Scenario ID + name + your initials. The Event Name appears in the heading of the full emails. The short notices name the trip by city and show the Tracking # once one exists. Note the time of each action to tell look-alike emails apart.
B23: TRACKING NUMBERS
B24: Format | C24: SLIN code + hyphen + 5 digits | D24: Example: 6200AE-00001. The SLIN is the one the Supervisor picks at approval.
B25: When it is issued | C25: First Supervisor approval only | D25: A request returned by the Prime and approved again keeps the same number. A request denied or cancelled before its first approval never gets one.
B26: Where it must appear | C26: Every message after approval | D26: Both approval emails, the authorize / return / deny notices, the submit emails on a resubmission, and every expense email. The expense report uses the same number as its estimate.
B27: Counter | C27: One sequence across all SLINs | D27: 00001, 00002, 00003 ... in approval order (Watch W7).
B29: WHICH COSTS ARE MULTIPLIED BY TRAVELERS
B30: Per traveler (x Travelers) | C30: Total Lodging Cost, Airfare, Baggage, Airport Parking | D30: Enter the amount for ONE traveler. Per Diem Meals is also per traveler.
B31: Trip-level (not multiplied) | C31: Rental Car, Gas, Parking, Tolls, Rideshare, Mileage, Shipping (to), Shipping (back) | D31: Enter the amount for the whole trip.
B32: Marked up by the multiplier | C32: Everything above except Per Diem Meals | D32: EWW is never marked up.
B34: THE MATH, IN ONE PLACE
B35: Nights | C35: Return date - Leave date
B36: Per Diem Meals (per traveler) | C36: 1.5 x M&IE + (Nights - 1, min 0) x M&IE | D36: First and last day are each 75% (1.5x combined); every day in between is 100%.
B37: Per Traveler Subtotal | C37: Per Diem + Total Lodging + Airfare + Airport Parking + Baggage
B38: Trip Lead Total | C38: Per Traveler Subtotal x Travelers + trip-level costs | D38: Internal figure (no markup).
B39: EWW Total | C39: Sum over travelers of (rate x hours) | D39: Entered by the Supervisor at review.
B40: Billable to Prime (ODC) | C40: (per-traveler costs x Travelers + trip-level costs) x multiplier + Per Diem x Travelers
B41: Grand Total to Prime | C41: Billable to Prime (ODC) + EWW Total | D41: The only total the Prime sees.
B42: GSA lodging limit | C42: Room Cost / Nights must be <= GSA Lodging Rate | D42: Fees and taxes do NOT count. Over the limit => 3 comparison quotes required.
B44: WHERE A NUMBER SHOWS UP
B45: Employee form | C45: Nights, Full Days, Per Diem, Per Traveler Subtotal, Trip Lead Total | D45: No markup figures for an Employee.
B46: My Estimates list / Supervisor queue | C46: Grand Total = Trip Lead Total + EWW (internal)
B47: Supervisor review | C47: All of the above + EWW, Grand Total, Billable to Prime (ODC), Grand Total to Prime, per-line Billable column | D47: Line items are per traveler / per trip, so they do not sum to the totals when Travelers > 1.
...

Sheet Scenarios
A1: Scenario index
A2: Eight scripted scenarios covering every role, every status, and every control. Progress columns fill in as you work the Steps and Emails tabs.
A4: ID | B4: Scenario | C4: Travel type | D4: Max travelers | E4: EWW travelers | F4: What it proves | G4: Steps | H4: Steps done | I4: Emails exp. | J4: Emails rcvd
A5: S1 | B5: Solo drive trip, under GSA, no EWW | C5: Drive (personal vehicle) | D5: 1 | E5: 0 | F5: Baseline. One traveler, no flights, no EWW. Proves the core math, the happy path through every role, a clean expense report (no variance), the tracking number, and the full email set. | G5: 20 | H5: =COUNTIFS(Steps!$A$5:$A$24,A5,Steps!$J$5:$J$24,"Pass")+COUNTIFS(Steps!$A$5:$A$24,A5,Steps!$J$5:$J$24,"Observe") -> 0 | I5: =Emails!B5 -> 8 | J5: =Emails!C5 -> 0
A6: S2 | B6: Fly + rental car, 2 travelers, 1 with EWW | C6: Fly + rental car | D6: 2 | E6: 1 | F6: Per-traveler vs trip-level math with two travelers, one EWW traveler (Traveler 2 has none), and the richest expense report: two categories >10% over, two additional (unestimated) categories, receipt add/remove and form Cancel. Proves EWW carries from the estimate to the expense exactly. | G6: 17 | H6: =COUNTIFS(Steps!$A$25:$A$41,A6,Steps!$J$25:$J$41,"Pass")+COUNTIFS(Steps!$A$25:$A$41,A6,Steps!$J$25:$J$41,"Observe") -> 0 | I6: =Emails!B6 -> 8 | J6: =Emails!C6 -> 0
A7: S3 | B7: Lodging limit rules (fees/taxes excluded, over-limit quotes) | C7: Fly, hotel conference | D7: 1 | E7: 1 | F7: The per diem lodging limit applies to the ROOM rate only. S3a proves taxes and fees do not trigger the limit. S3b proves an over-limit room rate forces three comparison quotes, and that the quotes flow to the Supervisor. | G7: 13 | H7: =COUNTIFS(Steps!$A$42:$A$54,A7,Steps!$J$42:$J$54,"Pass")+COUNTIFS(Steps!$A$42:$A$54,A7,Steps!$J$42:$J$54,"Observe") -> 0 | I7: =Emails!B7 -> 9 | J7: =Emails!C7 -> 0
A8: S4 | B8: Long stay, 4 travelers, 2 with EWW | C8: Fly + rideshare + shipping | D8: 4 | E8: 2 | F8: Maximum multiplier effect: 4 travelers, 10 nights, two EWW travelers with different rates and hours. Exercises traveler add/remove, an actual-date change on the expense side, and a variance on rideshare and return shipping. | G8: 11 | H8: =COUNTIFS(Steps!$A$55:$A$65,A8,Steps!$J$55:$J$65,"Pass")+COUNTIFS(Steps!$A$55:$A$65,A8,Steps!$J$55:$J$65,"Observe") -> 0 | I8: =Emails!B8 -> 8 | J8: =Emails!C8 -> 0
A9: S5 | B9: Edge dates: one night and same day | C9: Fly (1 night) / local (same day) | D9: 1 | E9: 1 | F9: GSA first/last-day rule at its boundaries. One night = two 75% days (1.5x M&IE, zero full days). Same day (0 nights) is an observation: record what the app produces and take it to the team (Watch W1 has the question written out). | G9: 8 | H9: =COUNTIFS(Steps!$A$66:$A$73,A9,Steps!$J$66:$J$73,"Pass")+COUNTIFS(Steps!$A$66:$A$73,A9,Steps!$J$66:$J$73,"Observe") -> 0 | I9: =Emails!B9 -> 9 | J9: =Emails!C9 -> 0
A10: S6 | B10: Validation rules + Supervisor return and resubmit | C10: Fly, 2 travelers | D10: 2 | E10: 1 | F10: Every blocking rule on the estimate form, then a Return round-trip: the Supervisor enters EWW and returns the estimate, the employee sees the note, corrects airfare and resubmits, and the EWW survives. | G10: 15 | H10: =COUNTIFS(Steps!$A$74:$A$88,A10,Steps!$J$74:$J$88,"Pass")+COUNTIFS(Steps!$A$74:$A$88,A10,Steps!$J$74:$J$88,"Observe") -> 0 | I10: =Emails!B10 -> 8 | J10: =Emails!C10 -> 0
A11: S7 | B11: Deny, return and cancel paths | C11: Fly, 1 traveler (light data) | D11: 1 | E11: 0 | F11: Every way an estimate can end other than paid: Supervisor deny, Prime return then deny, and employee cancel from draft and submitted. Denied requests are stored read-only. A returned request keeps its tracking number through re-approval. Math is light here; the focus is status, notes, tracking number and emails. | G11: 13 | H11: =COUNTIFS(Steps!$A$89:$A$101,A11,Steps!$J$89:$J$101,"Pass")+COUNTIFS(Steps!$A$89:$A$101,A11,Steps!$J$89:$J$101,"Observe") -> 0 | I11: =Emails!B11 -> 17 | J11: =Emails!C11 -> 0
A12: S8 | B12: Expense return and resubmit, expense deny | C12: Fly, 1 traveler (light data) | D12: 1 | E12: 0 | F12: The expense-side rejection paths. Two minimal authorized estimates: S8a's expense report is returned, corrected and resubmitted, then approved; S8b's is denied and stored read-only. | G12: 13 | H12: =COUNTIFS(Steps!$A$102:$A$114,A12,Steps!$J$102:$J$114,"Pass")+COUNTIFS(Steps!$A$102:$A$114,A12,Steps!$J$102:$J$114,"Observe") -> 0 | I12: =Emails!B12 -> 19 | J12: =Emails!C12 -> 0

Sheet Steps
A1: Run-sheet — every step of every scenario
A2: Do the step, read the Check column, set Status. "Observe" = record what you see, no pass/fail (policy or known-risk items).
A4: Scenario | B4: Step | C4: Persona | D4: Estimate | E4: Do this | F4: Controls | G4: Check / expect | H4: Emails | I4: Email IDs | J4: Status | K4: Your notes
A5: S1 | B5: 1 | C5: Employee | D5: S1 | E5: Travel > My Estimates > New Travel Estimate. Type Event Name, City, pick State from the list, pick a Contract. | F5: E01, E02, E03, E04 | G5: Rate fields auto-fill from the GSA lookup (any value is fine - you overwrite them next). | H5: 0
A6: S1 | B6: 2 | C6: Employee | D6: S1 | E6: Set Leave Date and Return Date. Leave Travelers at 1. | F6: E05, E06, E07 | G6: Checkpoints A1 (Nights) and A2 (Full Days). | H6: 0
A7: S1 | B7: 3 | C7: Employee | D7: S1 | E7: AFTER the lookup finishes, overwrite GSA Lodging Rate and Meals (M&IE) Rate with the scripted values. Click a field, type the number, Tab out. | F7: E11, E12, E33 | G7: Field clears on click and reformats as $X.XX on Tab. Checkpoint A3 (Per Diem Meals Total). | H7: 0
A8: S1 | B8: 4 | C8: Employee | D8: S1 | E8: Enter Room Cost, Total Lodging Cost, Lodging Fees, Lodging Taxes, then Mileage, Gas, Parking, Tolls. Leave everything else at $0.00. | F8: E13, E14, E15, E16, E25, E26, E27, E29 | G8: No red GSA warning appears. Checkpoints A4 and A5. Employee view shows only Per Traveler Subtotal and Trip Lead Total (no markup figures). | H8: 0
A9: S1 | B9: 5 | C9: Employee | D9: S1 | E9: Click Save as Draft. Then open the draft from the Pending card (Edit Draft). | F9: E30, L01, G03, L03 | G9: Toast says "Draft saved." Row shows status draft. Every value and the Event Name persist after reopening. No email for a draft. | H9: 0
A10: S1 | B10: 6 | C10: Employee | D10: S1 | E10: Click Submit Estimate. | F10: E31, G03 | G10: Toast "Travel estimate submitted." Row moves to status submitted. Checkpoint B1. No tracking number exists yet. | H10: 2 | I10: S1-E1, S1-E2
A11: S1 | B11: 7 | C11: Supervisor | D11: S1 | E11: Switch Role > Supervisor. Travel > Approvals. Find the estimate under "Estimates Needing Approval" and click Review. Click Close once, then click Review again. | F11: G01, S01, S11, S12 | G11: Close dismisses the review without a decision. Queue Grand Total matches B1. Form is read-only. Fee Multiplier Used shows 1.1274x (if not, stop and fix Setup C5). Tracking Number reads "Assigned on approval". | H11: 0
A12: S1 | B12: 8 | C12: Supervisor | D12: S1 | E12: Leave every EWW rate/hours field at $0.00 / 0 (no EWW on this trip). | F12: S02, S03 | G12: Checkpoints C1-C6 and the billable line column (C-L rows). | H12: 0
A13: S1 | B13: 9 | C13: Supervisor | D13: S1 | E13: Billing Assignment: pick Contract, then Task Order, then SLIN. Click Approve. | F13: S04, S05, S06, S08 | G13: Task Order list filters to the chosen Contract; SLIN list filters to the chosen Task Order. Queue drops the row. Tracking # = the SLIN code you picked, a hyphen, and 5 digits (e.g. 6200AE-00001). Record it. It must appear in both approval emails. | H13: 2 | I13: S1-E3, S1-E4
A14: S1 | B14: 10 | C14: Prime | D14: S1 | E14: Switch Role > Prime. Travel > Travel Authorizations. Check the queue row, then click Review. | F14: G01, P01, P07 | G14: Queue Tracking # matches the email; Grand Total = D2. Review form shows marked-up amounts only (no Room Cost, Fees, Taxes, GSA warning). Checkpoints E1-E4 must match the queue to the cent. | H14: 0
A15: S1 | B15: 11 | C15: Prime | D15: S1 | E15: Click Authorize Travel. | F15: P02 | G15: Queue drops the row. The email names the trip and shows the tracking number. | H15: 1 | I15: S1-E5
A16: S1 | B16: 12 | C16: Employee | D16: S1 | E16: Switch Role > Employee. Travel > My Estimates. Open the estimate (View). | F16: G01, L01 | G16: Status approved. Read-only detail shows the same Tracking Number. Checkpoint D1. | H16: 0
A17: S1 | B17: 13 | C17: Employee | D17: S1 | E17: Travel > My Expenses > New Travel Expense Report. Pick the estimate from "Authorized Estimate". | F17: X01 | G17: Dropdown label ends with [Tracking #]. Dates, travelers and M&IE prefill. Only categories with an estimate > $0 appear (Lodging, Gas, Parking, Tolls, Mileage). EWW shows as a read-only total ($0.00 here). Checkpoint X-A. | H17: 0
A18: S1 | B18: 14 | C18: Employee | D18: S1 | E18: Change Actual Leave Date to 11/10, watch Nights and Per Diem, then set it back to 11/09. Also retype the Actual Return Date (11/12). | F18: X02, X03 | G18: Nights drops to 2 and Per Diem Meals Total recalculates live, then both return to the original values. | H18: 0
A19: S1 | B19: 15 | C19: Employee | D19: S1 | E19: Enter the Actual cost for each visible category. Upload one receipt (image or PDF) in every category that has an amount. | F19: X08, X09, E33 | G19: No variance box appears for any category (all within 10%). Checkpoint X-B (live totals) and X-C (category table). | H19: 0
A20: S1 | B20: 16 | C20: Employee | D20: S1 | E20: Save as Draft, then reopen it (Edit Draft). | F20: X15, X18 | G20: Actuals, receipts and totals persist. No email for a draft. | H20: 0
A21: S1 | B21: 17 | C21: Employee | D21: S1 | E21: Submit Expense Report. | F21: X16 | G21: Report shows in My Expense Reports as submitted. Checkpoint X-D. The estimate now reads expensed. Both emails show the trip, tracking number, actual vs estimated by category, and totals. | H21: 2 | I21: S1-E6, S1-E7
A22: S1 | B22: 18 | C22: Supervisor | D22: S1 | E22: Switch Role > Supervisor. Approvals > Expense Reports Needing Approval > Review. | F22: G01, V01, V07 | G22: Header counts: Categories >10% Over = 0, Added Categories = 0. Form is read-only; receipts open. | H22: 0
A23: S1 | B23: 19 | C23: Supervisor | D23: S1 | E23: Click Approve (finalizes reimbursement). | F23: V02 | G23: Row leaves the queue. | H23: 1 | I23: S1-E8
A24: S1 | B24: 20 | C24: Employee | D24: S1 | E24: Switch Role > Employee. Check My Estimates and My Expenses. | F24: G01, L03, L02 | G24: Expense status approved. Estimate sits in the Paid / Cancelled card as paid and has NO red cancel (x). | H24: 0
A25: S2 | B25: 1 | C25: Employee | D25: S2 | E25: New Travel Estimate. Type Event Name, City, State, pick Contract. Set Leave and Return Dates. | F25: E01, E02, E03, E04, E05, E06 | G25: Checkpoints A1, A2. | H25: 0
A26: S2 | B26: 2 | C26: Employee | D26: S2 | E26: Set Travelers to 2. Pick any roster employee for Traveler 2. | F26: E07, E08 | G26: Traveler 1 is locked ("You"). The Traveler 2 list does not offer the person already chosen. | H26: 0
A27: S2 | B27: 3 | C27: Employee | D27: S2 | E27: Overwrite GSA Lodging Rate and M&IE Rate. Enter Room Cost, Total Lodging, Fees, Taxes, Airfare, Airport Parking, Rental Car, Gas, Parking, Shipping (to), Shipping (back). Leave Baggage and Tolls at $0.00. | F27: E11, E12, E13, E14, E15, E16, E19, E21, E22, E23, E24, E25, E26, E33 | G27: Checkpoints A3-A5. Lodging, airfare and airport parking are PER TRAVELER (the app multiplies by 2); rental car, gas, parking and shipping are TRIP-LEVEL (not multiplied). There are no EWW fields on this form. | H27: 0
A28: S2 | B28: 4 | C28: Employee | D28: S2 | E28: Submit Estimate. | F28: E31, G03 | G28: Checkpoint B1. Open each email: the EWW table lists both travelers at $0.00. | H28: 2 | I28: S2-E1, S2-E2
A29: S2 | B29: 5 | C29: Supervisor | D29: S2 | E29: Switch Role > Supervisor. Approvals > Review the estimate. | F29: G01, S01, S12 | G29: Read-only copy of the form. Note the line-item values are per traveler. | H29: 0
A30: S2 | B30: 6 | C30: Supervisor | D30: S2 | E30: Enter EWW (payroll-verified): Traveler 1 rate 62.50, hours 12. Traveler 2 stays $0.00 / 0. | F30: S02, S03 | G30: EWW Cost for Traveler 1 updates live; EWW Total, Grand Total and both Prime figures update. Checkpoints C1-C7 and the billable line rows. | H30: 0
A31: S2 | B31: 7 | C31: Supervisor | D31: S2 | E31: Assign Contract / Task Order / SLIN and click Approve. | F31: S04, S05, S06, S08 | G31: Emails now include the EWW table (Traveler 1 = $750.00) and the tracking number. Tracking # = the SLIN code you picked, a hyphen, and 5 digits (e.g. 6200AE-00001). Record it. | H31: 2 | I31: S2-E3, S2-E4
A32: S2 | B32: 8 | C32: Prime | D32: S2 | E32: Prime queue: check Tracking # and Grand Total, open Review, then Authorize Travel. | F32: G01, P01, P02, P07 | G32: Checkpoints D2 and E1-E4. The Prime form total must equal the queue total to the cent (every marked-up line is rounded first). | H32: 1 | I32: S2-E5
A33: S2 | B33: 9 | C33: Employee | D33: S2 | E33: Travel > My Expenses > New Travel Expense Report. Pick the estimate, change nothing, then click Cancel on the form. | F33: X01, X17 | G33: Returns to the list; nothing saved. Then start the report again. | H33: 0
A34: S2 | B34: 10 | C34: Employee | D34: S2 | E34: Select the estimate again and read the EWW box. Do not look for EWW rate or hours fields. | F34: X19 | G34: There are no EWW fields to type. A read-only EWW Total shows $750.00, the exact total payroll verified on the estimate (checkpoint X-A1). | H34: 0
A35: S2 | B35: 11 | C35: Employee | D35: S2 | E35: Enter the Actual costs for the eight visible categories. | F35: X05, X08, E33 | G35: Variance boxes appear for Airfare and Gas ONLY (checkpoint X-C). Totals show EWW $750.00 and Variance +$338.40 once all actuals are in. | H35: 0
A36: S2 | B36: 12 | C36: Employee | D36: S2 | E36: Click Submit Expense Report with the variance notes still blank. | F36: X16 | G36: Blocked with "Explain the variance for ... " naming the first category. Type the notes from the table and continue. | H36: 0
A37: S2 | B37: 13 | C37: Employee | D37: S2 | E37: Additional Expenses: add Baggage and Tolls from "+ Add an expense category". Enter the actuals. Add Rideshare, then remove it with the x. | F37: X12, X14 | G37: Estimated shows "-" for added rows. Submit is blocked until each added row has a note ("Explain why ... wasn't on the original estimate"). | H37: 0
A38: S2 | B38: 14 | C38: Employee | D38: S2 | E38: Fill in the notes for Baggage and Tolls. Upload a receipt on Airfare, remove it with the x, upload it again. Upload a receipt on every other category with an amount. | F38: X13, X09, X10, X11 | G38: Thumbnails show; removed receipt disappears. | H38: 0
A39: S2 | B39: 15 | C39: Employee | D39: S2 | E39: Save as Draft, reopen with Edit Draft, then Submit Expense Report. | F39: X15, X18, X16 | G39: Notes, additional rows and receipts persist. Checkpoints X-B, X-C, X-D. Both emails list the explanations. | H39: 2 | I39: S2-E6, S2-E7
A40: S2 | B40: 16 | C40: Supervisor | D40: S2 | E40: Approvals > Expense Reports Needing Approval > Review. | F40: G01, V01, V07 | G40: Header: Categories >10% Over = 2, Added Categories = 2. Variance explanations are visible. | H40: 0
A41: S2 | B41: 17 | C41: Supervisor | D41: S2 | E41: Approve. | F41: V02 | G41: Estimate becomes paid. | H41: 1 | I41: S2-E8
...

Sheet S1
A1: S1 — Solo drive trip, under GSA, no EWW
A2: Baseline. One traveler, no flights, no EWW. Proves the core math, the happy path through every role, a clean expense report (no variance), the tracking number, and the full email set.
A3: Travel type: Drive (personal vehicle) | Expected emails: 8 | Fee multiplier from Setup tab
A5: 1. INPUTS — type these exactly (blue)
A6: Ref | B6: Field / what to read | C6: Screen label / how it is calculated | D6: S1
B7: Event Name | C7: Add your initials at the end | D7: S1 Regional Workshop - xx
B8: City | D8: Columbia
B9: State | C9: Pick from the list | D9: SC
B10: Contract | C10: Pick any contract; note which one | D10: (any)
B11: Leave Date | D11: 46335
B12: Return Date | D12: 46338
B13: Travelers | C13: Traveler 2-4: pick any roster employee | D13: 1
B14: GSA Lodging Rate (per night) | C14: Overwrite AFTER the lookup finishes | D14: 110
B15: Meals (M&IE) Rate (per day) | C15: Overwrite AFTER the lookup finishes | D15: 68
B16: Room Cost (subject to per diem limit) | C16: Per traveler, whole stay | D16: 306
B17: Total Lodging Cost (incl. taxes & fees) | C17: Per traveler, whole stay | D17: 368.25
B18: Lodging Fees | C18: Recorded only | D18: 24
B19: Lodging Taxes | C19: Recorded only | D19: 38.25
B20: Airfare (avg) | C20: Per traveler | D20: 0
B21: Baggage | C21: Per traveler | D21: 0
B22: Airport Parking | C22: Per traveler | D22: 0
B23: Shipping (to) | C23: Trip-level | D23: 0
B24: Shipping (back) | C24: Trip-level | D24: 0
... B30: Mileage (Personal Vehicle) | C30: Trip-level | D30: 187.6
B31: Entered by the SUPERVISOR at review (not on the submit form)
B32: Traveler 1 EWW Rate (per hour) | C32: Supervisor review > EWW Rate | D32: 0
B33: Traveler 1 EWW Hours | D33: 0
B34: Traveler 2 EWW Rate (per hour) | D34: 0
B35: Traveler 2 EWW Hours | D35: 0
B36: Traveler 3 EWW Rate (per hour) | D36: 0
B37: Traveler 3 EWW Hours | D37: 0
B38: Traveler 4 EWW Rate (per hour) | D38: 0
B39: Traveler 4 EWW Hours | D39: 0
B40: EWW already saved when submitted? (1 = yes) | C40: Only a resubmission after a Supervisor return carries EWW | D40: 0
A42: 2. EXPECTED MATH — live formulas (read these to follow the arithmetic)
A43: Ref | B43: Field / what to read | C43: Screen label / how it is calculated | D43: S1
B44: Nights | C44: Return Date - Leave Date (never below 0) | D44: =MAX(0,D12-D11) -> 3
B45: Full Days (1x) | C45: Nights - 1, minimum 0 | D45: =MAX(D44-1,0) -> 2
B46: Per Diem Meals Total (per traveler) | C46: 1.5 x M&IE + Full Days x M&IE | D46: =1.5*D15+D45*D15 -> 238
B47: Per-traveler costs (excl. meals) | C47: Total Lodging + Airfare + Airport Parking + Baggage | D47: =D17+D20+D22+D21 -> 368.25
...

Sheet S2
A1: S2 — Fly + rental car, 2 travelers, 1 with EWW
A2: Per-traveler vs trip-level math with two travelers, one EWW traveler (Traveler 2 has none), and the richest expense report: two categories >10% over, two additional (unestimated) categories, receipt add/remove and form Cancel. Proves EWW carries from the estimate to the expense exactly.
A3: Travel type: Fly + rental car | Expected emails: 8 | Fee multiplier from Setup tab
A5: 1. INPUTS — type these exactly (blue)
A6: Ref | B6: Field / what to read | C6: Screen label / how it is calculated | D6: S2
B7: Event Name | C7: Add your initials at the end | D7: S2 Customer Site Visit - xx
B8: City | D8: Austin
B9: State | C9: Pick from the list | D9: TX
B10: Contract | C10: Pick any contract; note which one | D10: (any)
B11: Leave Date | D11: 46342
B12: Return Date | D12: 46345
B13: Travelers | C13: Traveler 2-4: pick any roster employee | D13: 2
B14: GSA Lodging Rate (per night) | C14: Overwrite AFTER the lookup finishes | D14: 150
B15: Meals (M&IE) Rate (per day) | C15: Overwrite AFTER the lookup finishes | D15: 74
B16: Room Cost (subject to per diem limit) | C16: Per traveler, whole stay | D16: 420
B17: Total Lodging Cost (incl. taxes & fees) | C17: Per traveler, whole stay | D17: 513.8
B18: Lodging Fees | C18: Recorded only | D18: 35
B19: Lodging Taxes | C19: Recorded only | D19: 58.8
B20: Airfare (avg) | C20: Per traveler | D20: 385
B21: Baggage | C21: Per traveler | D21: 0
B22: Airport Parking | C22: Per traveler | D22: 60
B23: Shipping (to) | C23: Trip-level | D23: 85
B24: Shipping (back) | C24: Trip-level | D24: 85
... B30: Mileage (Personal Vehicle) | C30: Trip-level | D30: 0
B31: Entered by the SUPERVISOR at review (not on the submit form)
B32: Traveler 1 EWW Rate (per hour) | C32: Supervisor review > EWW Rate | D32: 62.5
B33: Traveler 1 EWW Hours | D33: 12
B34: Traveler 2 EWW Rate (per hour) | D34: 0
B35: Traveler 2 EWW Hours | D35: 0
B36: Traveler 3 EWW Rate (per hour) | D36: 0
B37: Traveler 3 EWW Hours | D37: 0
B38: Traveler 4 EWW Rate (per hour) | D38: 0
B39: Traveler 4 EWW Hours | D39: 0
B40: EWW already saved when submitted? (1 = yes) | C40: Only a resubmission after a Supervisor return carries EWW | D40: 0
A42: 2. EXPECTED MATH — live formulas (read these to follow the arithmetic)
A43: Ref | B43: Field / what to read | C43: Screen label / how it is calculated | D43: S2
B44: Nights | C44: Return Date - Leave Date (never below 0) | D44: =MAX(0,D12-D11) -> 3
B45: Full Days (1x) | C45: Nights - 1, minimum 0 | D45: =MAX(D44-1,0) -> 2
B46: Per Diem Meals Total (per traveler) | C46: 1.5 x M&IE + Full Days x M&IE | D46: =1.5*D15+D45*D15 -> 259
B47: Per-traveler costs (excl. meals) | C47: Total Lodging + Airfare + Airport Parking + Baggage | D47: =D17+D20+D22+D21 -> 958.8
...

Sheet S3
A1: S3 — Lodging limit rules (fees/taxes excluded, over-limit quotes)
A2: The per diem lodging limit applies to the ROOM rate only. S3a proves taxes and fees do not trigger the limit. S3b proves an over-limit room rate forces three comparison quotes, and that the quotes flow to the Supervisor.
A3: Travel type: Fly, hotel conference | Expected emails: 9 | Fee multiplier from Setup tab
A5: 1. INPUTS — type these exactly (blue)
A6: Ref | B6: Field / what to read | C6: Screen label / how it is calculated | D6: S3a | G6: S3b
B7: Event Name | C7: Add your initials at the end | D7: S3a Fees-Taxes Excluded - xx | G7: S3b Over Limit With Quotes - xx
B8: City | D8: Nashville | G8: Memphis
B9: State | C9: Pick from the list | D9: TN | G9: TN
B10: Contract | C10: Pick any contract; note which one | D10: (any) | G10: (any)
B11: Leave Date | D11: 46349 | G11: 46349
B12: Return Date | D12: 46352 | G12: 46352
B13: Travelers | C13: Traveler 2-4: pick any roster employee | D13: 1 | G13: 1
B14: GSA Lodging Rate (per night) | C14: Overwrite AFTER the lookup finishes | D14: 140 | G14: 140
B15: Meals (M&IE) Rate (per day) | C15: Overwrite AFTER the lookup finishes | D15: 69 | G15: 69
B16: Room Cost (subject to per diem limit) | C16: Per traveler, whole stay | D16: 405 | G16: 468
B17: Total Lodging Cost (incl. taxes & fees) | C17: Per traveler, whole stay | D17: 511.5 | G17: 584.55
B18: Lodging Fees | C18: Recorded only | D18: 45 | G18: 45
B19: Lodging Taxes | C19: Recorded only | D19: 61.5 | G19: 71.55
B20: Airfare (avg) | C20: Per traveler | D20: 298 | G20: 298
B21: Baggage | C21: Per traveler | D21: 35 | G21: 35
B22: Airport Parking | C22: Per traveler | D22: 54 | G22: 54
B23: Shipping (to) | C23: Trip-level | D23: 0 | G23: 0
B24: Shipping (back) | C24: Trip-level | D24: 0 | G24: 0
... B30: Mileage (Personal Vehicle) | C30: Trip-level | D30: 0 | G30: 0
B31: Entered by the SUPERVISOR at review (not on the submit form)
B32: Traveler 1 EWW Rate (per hour) | C32: Supervisor review > EWW Rate | D32: 0 | G32: 52
B33: Traveler 1 EWW Hours | D33: 0 | G33: 5
B34: Traveler 2 EWW Rate (per hour) | D34: 0 | G34: 0
B35: Traveler 2 EWW Hours | D35: 0 | G35: 0
B36: Traveler 3 EWW Rate (per hour) | D36: 0 | G36: 0
B37: Traveler 3 EWW Hours | D37: 0 | G37: 0
B38: Traveler 4 EWW Rate (per hour) | D38: 0 | G38: 0
B39: Traveler 4 EWW Hours | D39: 0 | G39: 0
B40: EWW already saved when submitted? (1 = yes) | C40: Only a resubmission after a Supervisor return carries EWW | D40: 0 | G40: 0
B41: Comparison quote 1 nightly rate | C41: Upload Comparison Quotes modal | G41: 138
B42: Comparison quote 2 nightly rate | G42: 149
B43: Comparison quote 3 nightly rate | G43: 152
A45: 2. EXPECTED MATH — live formulas (read these to follow the arithmetic)
A46: Ref | B46: Field / what to read | C46: Screen label / how it is calculated | D46: S3a | G46: S3b
B47: Nights | C47: Return Date - Leave Date (never below 0) | D47: =MAX(0,D12-D11) -> 3 | G47: =MAX(0,G12-G11) -> 3
...

Sheet S4
A1: S4 — Long stay, 4 travelers, 2 with EWW
A2: Maximum multiplier effect: 4 travelers, 10 nights, two EWW travelers with different rates and hours. Exercises traveler add/remove, an actual-date change on the expense side, and a variance on rideshare and return shipping.
A3: Travel type: Fly + rideshare + shipping | Expected emails: 8 | Fee multiplier from Setup tab
A5: 1. INPUTS — type these exactly (blue)
A6: Ref | B6: Field / what to read | C6: Screen label / how it is calculated | D6: S4
B7: Event Name | C7: Add your initials at the end | D7: S4 Training Cohort Onsite - xx
B8: City | D8: San Diego
B9: State | C9: Pick from the list | D9: CA
B10: Contract | C10: Pick any contract; note which one | D10: (any)
B11: Leave Date | D11: 46357
B12: Return Date | D12: 46367
B13: Travelers | C13: Traveler 2-4: pick any roster employee | D13: 4
B14: GSA Lodging Rate (per night) | C14: Overwrite AFTER the lookup finishes | D14: 189
B15: Meals (M&IE) Rate (per day) | C15: Overwrite AFTER the lookup finishes | D15: 79
B16: Room Cost (subject to per diem limit) | C16: Per traveler, whole stay | D16: 1764
B17: Total Lodging Cost (incl. taxes & fees) | C17: Per traveler, whole stay | D17: 2119.62
B18: Lodging Fees | C18: Recorded only | D18: 120
B19: Lodging Taxes | C19: Recorded only | D19: 235.62
B20: Airfare (avg) | C20: Per traveler | D20: 512
B21: Baggage | C21: Per traveler | D21: 70
B22: Airport Parking | C22: Per traveler | D22: 96
B23: Shipping (to) | C23: Trip-level | D23: 224
B24: Shipping (back) | C24: Trip-level | D24: 190
... B30: Mileage (Personal Vehicle) | C30: Trip-level | D30: 0
B31: Entered by the SUPERVISOR at review (not on the submit form)
B32: Traveler 1 EWW Rate (per hour) | C32: Supervisor review > EWW Rate | D32: 55
B33: Traveler 1 EWW Hours | D33: 8
B34: Traveler 2 EWW Rate (per hour) | D34: 0
B35: Traveler 2 EWW Hours | D35: 0
B36: Traveler 3 EWW Rate (per hour) | D36: 48.75
B37: Traveler 3 EWW Hours | D37: 16
B38: Traveler 4 EWW Rate (per hour) | D38: 0
B39: Traveler 4 EWW Hours | D39: 0
B40: EWW already saved when submitted? (1 = yes) | C40: Only a resubmission after a Supervisor return carries EWW | D40: 0
A42: 2. EXPECTED MATH — live formulas (read these to follow the arithmetic)
A43: Ref | B43: Field / what to read | C43: Screen label / how it is calculated | D43: S4
B44: Nights | C44: Return Date - Leave Date (never below 0) | D44: =MAX(0,D12-D11) -> 10
B45: Full Days (1x) | C45: Nights - 1, minimum 0 | D45: =MAX(D44-1,0) -> 9
B46: Per Diem Meals Total (per traveler) | C46: 1.5 x M&IE + Full Days x M&IE | D46: =1.5*D15+D45*D15 -> 829.5
B47: Per-traveler costs (excl. meals) | C47: Total Lodging + Airfare + Airport Parking + Baggage | D47: =D17+D20+D22+D21 -> 2797.62
...

Sheet S5
A1: S5 — Edge dates: one night and same day
A2: GSA first/last-day rule at its boundaries. One night = two 75% days (1.5x M&IE, zero full days). Same day (0 nights) is an observation: record what the app produces and take it to the team (Watch W1 has the question written out).
A3: Travel type: Fly (1 night) / local (same day) | Expected emails: 9 | Fee multiplier from Setup tab
A5: 1. INPUTS — type these exactly (blue)
A6: Ref | B6: Field / what to read | C6: Screen label / how it is calculated | D6: S5a | G6: S5b
B7: Event Name | C7: Add your initials at the end | D7: S5a One Night Trip - xx | G7: S5b Same Day Trip - xx
B8: City | D8: Raleigh | G8: Charlotte
B9: State | C9: Pick from the list | D9: NC | G9: NC
B10: Contract | C10: Pick any contract; note which one | D10: (any) | G10: (any)
B11: Leave Date | D11: 46370 | G11: 46373
B12: Return Date | D12: 46371 | G12: 46373
B13: Travelers | C13: Traveler 2-4: pick any roster employee | D13: 1 | G13: 1
B14: GSA Lodging Rate (per night) | C14: Overwrite AFTER the lookup finishes | D14: 135 | G14: 130
B15: Meals (M&IE) Rate (per day) | C15: Overwrite AFTER the lookup finishes | D15: 64 | G15: 64
B16: Room Cost (subject to per diem limit) | C16: Per traveler, whole stay | D16: 128 | G16: 0
B17: Total Lodging Cost (incl. taxes & fees) | C17: Per traveler, whole stay | D17: 145.92 | G17: 0
B18: Lodging Fees | C18: Recorded only | D18: 0 | G18: 0
B19: Lodging Taxes | C19: Recorded only | D19: 17.92 | G19: 0
B20: Airfare (avg) | C20: Per traveler | D20: 244 | G20: 0
B21: Baggage | C21: Per traveler | D21: 0 | G21: 0
B22: Airport Parking | C22: Per traveler | D22: 0 | G22: 0
B23: Shipping (to) | C23: Trip-level | D23: 0 | G23: 0
B24: Shipping (back) | C24: Trip-level | D24: 0 | G24: 0
... B30: Mileage (Personal Vehicle) | C30: Trip-level | D30: 0 | G30: 0
B31: Entered by the SUPERVISOR at review (not on the submit form)
B32: Traveler 1 EWW Rate (per hour) | C32: Supervisor review > EWW Rate | D32: 40 | G32: 0
B33: Traveler 1 EWW Hours | D33: 6 | G33: 0
B34: Traveler 2 EWW Rate (per hour) | D34: 0 | G34: 0
B35: Traveler 2 EWW Hours | D35: 0 | G35: 0
B36: Traveler 3 EWW Rate (per hour) | D36: 0 | G36: 0
B37: Traveler 3 EWW Hours | D37: 0 | G37: 0
B38: Traveler 4 EWW Rate (per hour) | D38: 0 | G38: 0
B39: Traveler 4 EWW Hours | D39: 0 | G39: 0
B40: EWW already saved when submitted? (1 = yes) | C40: Only a resubmission after a Supervisor return carries EWW | D40: 0 | G40: 0
A42: 2. EXPECTED MATH — live formulas (read these to follow the arithmetic)
A43: Ref | B43: Field / what to read | C43: Screen label / how it is calculated | D43: S5a | G43: S5b
B44: Nights | C44: Return Date - Leave Date (never below 0) | D44: =MAX(0,D12-D11) -> 1 | G44: =MAX(0,G12-G11) -> 0
B45: Full Days (1x) | C45: Nights - 1, minimum 0 | D45: =MAX(D44-1,0) -> 0 | G45: =MAX(G44-1,0) -> 0
B46: Per Diem Meals Total (per traveler) | C46: 1.5 x M&IE + Full Days x M&IE | D46: =1.5*D15+D45*D15 -> 96 | G46: =1.5*G15+G45*G15 -> 96
B47: Per-traveler costs (excl. meals) | C47: Total Lodging + Airfare + Airport Parking + Baggage | D47: =D17+D20+D22+D21 -> 389.92 | G47: =G17+G20+G22+G21 -> 0
...

Sheet S6
A1: S6 — Validation rules + Supervisor return and resubmit
A2: Every blocking rule on the estimate form, then a Return round-trip: the Supervisor enters EWW and returns the estimate, the employee sees the note, corrects airfare and resubmits, and the EWW survives.
A3: Travel type: Fly, 2 travelers | Expected emails: 8 | Fee multiplier from Setup tab
A5: 1. INPUTS — type these exactly (blue)
A6: Ref | B6: Field / what to read | C6: Screen label / how it is calculated | D6: S6 v1 | G6: S6 v2
B7: Event Name | C7: Add your initials at the end | D7: S6 Return And Resubmit - xx | G7: S6 Return And Resubmit - xx
B8: City | D8: Houston | G8: Houston
B9: State | C9: Pick from the list | D9: TX | G9: TX
B10: Contract | C10: Pick any contract; note which one | D10: (any) | G10: (any)
B11: Leave Date | D11: 46363 | G11: 46363
B12: Return Date | D12: 46366 | G12: 46366
B13: Travelers | C13: Traveler 2-4: pick any roster employee | D13: 2 | G13: 2
B14: GSA Lodging Rate (per night) | C14: Overwrite AFTER the lookup finishes | D14: 142 | G14: 142
B15: Meals (M&IE) Rate (per day) | C15: Overwrite AFTER the lookup finishes | D15: 71 | G15: 71
B16: Room Cost (subject to per diem limit) | C16: Per traveler, whole stay | D16: 396 | G16: 396
B17: Total Lodging Cost (incl. taxes & fees) | C17: Per traveler, whole stay | D17: 477.46 | G17: 477.46
B18: Lodging Fees | C18: Recorded only | D18: 28 | G18: 28
B19: Lodging Taxes | C19: Recorded only | D19: 53.46 | G19: 53.46
B20: Airfare (avg) | C20: Per traveler | D20: 640 | G20: 512
B21: Baggage | C21: Per traveler | D21: 35 | G21: 35
B22: Airport Parking | C22: Per traveler | D22: 48 | G22: 48
B23: Shipping (to) | C23: Trip-level | D23: 0 | G23: 0
B24: Shipping (back) | C24: Trip-level | D24: 0 | G24: 0
... B30: Mileage (Personal Vehicle) | C30: Trip-level | D30: 0 | G30: 0
B31: Entered by the SUPERVISOR at review (not on the submit form)
B32: Traveler 1 EWW Rate (per hour) | C32: Supervisor review > EWW Rate | D32: 45 | G32: 45
B33: Traveler 1 EWW Hours | D33: 10 | G33: 10
B34: Traveler 2 EWW Rate (per hour) | D34: 0 | G34: 0
B35: Traveler 2 EWW Hours | D35: 0 | G35: 0
B36: Traveler 3 EWW Rate (per hour) | D36: 0 | G36: 0
B37: Traveler 3 EWW Hours | D37: 0 | G37: 0
B38: Traveler 4 EWW Rate (per hour) | D38: 0 | G38: 0
B39: Traveler 4 EWW Hours | D39: 0 | G39: 0
B40: EWW already saved when submitted? (1 = yes) | C40: Only a resubmission after a Supervisor return carries EWW | D40: 0 | G40: 1
A42: 2. EXPECTED MATH — live formulas (read these to follow the arithmetic)
A43: Ref | B43: Field / what to read | C43: Screen label / how it is calculated | D43: S6 v1 | G43: S6 v2
B44: Nights | C44: Return Date - Leave Date (never below 0) | D44: =MAX(0,D12-D11) -> 3 | G44: =MAX(0,G12-G11) -> 3
B45: Full Days (1x) | C45: Nights - 1, minimum 0 | D45: =MAX(D44-1,0) -> 2 | G45: =MAX(G44-1,0) -> 2
B46: Per Diem Meals Total (per traveler) | C46: 1.5 x M&IE + Full Days x M&IE | D46: =1.5*D15+D45*D15 -> 248.5 | G46: =1.5*G15+G45*G15 -> 248.5
B47: Per-traveler costs (excl. meals) | C47: Total Lodging + Airfare + Airport Parking + Baggage | D47: =D17+D20+D22+D21 -> 1200.46 | G47: =G17+G20+G22+G21 -> 1072.46
...

Sheet S7
A1: S7 — Deny, return and cancel paths
A2: Every way an estimate can end other than paid: Supervisor deny, Prime return then deny, and employee cancel from draft and submitted. Denied requests are stored read-only. A returned request keeps its tracking number through re-approval. Math is light here; the focus is status, notes, tracking number and emails.
A3: Travel type: Fly, 1 traveler (light data) | Expected emails: 17 | Fee multiplier from Setup tab
A5: 1. INPUTS — type these exactly (blue)
A6: Ref | B6: Field / what to read | C6: Screen label / how it is calculated | D6: S7a | G6: S7b | J6: S7c-1 | M6: S7c-2
B7: Event Name | C7: Add your initials at the end | D7: S7a Supervisor Deny - xx | G7: S7b Prime Return Then Deny - xx | J7: S7c Cancel From Draft - xx | M7: S7c Cancel After Submit - xx
B8: City | D8: Detroit | G8: Denver | J8: Boise | M8: Omaha
B9: State | C9: Pick from the list | D9: MI | G9: CO | J9: ID | M9: NE
B10: Contract | C10: Pick any contract; note which one | D10: (any) | G10: (any) | J10: (any) | M10: (any)
B11: Leave Date | D11: 46358 | G11: 46358 | J11: 46358 | M11: 46358
B12: Return Date | D12: 46360 | G12: 46360 | J12: 46360 | M12: 46360
B13: Travelers | C13: Traveler 2-4: pick any roster employee | D13: 1 | G13: 1 | J13: 1 | M13: 1
B14: GSA Lodging Rate (per night) | C14: Overwrite AFTER the lookup finishes | D14: 120 | G14: 120 | J14: 120 | M14: 120
B15: Meals (M&IE) Rate (per day) | C15: Overwrite AFTER the lookup finishes | D15: 59 | G15: 59 | J15: 59 | M15: 59
B16: Room Cost (subject to per diem limit) | C16: Per traveler, whole stay | D16: 224 | G16: 224 | J16: 224 | M16: 224
B17: Total Lodging Cost (incl. taxes & fees) | C17: Per traveler, whole stay | D17: 248.64 | G17: 248.64 | J17: 248.64 | M17: 248.64
B18: Lodging Fees | C18: Recorded only | D18: 0 | G18: 0 | J18: 0 | M18: 0
B19: Lodging Taxes | C19: Recorded only | D19: 24.64 | G19: 24.64 | J19: 24.64 | M19: 24.64
B20: Airfare (avg) | C20: Per traveler | D20: 300 | G20: 326 | J20: 276 | M20: 290
B21: Baggage | C21: Per traveler | D21: 0 | G21: 0 | J21: 0 | M21: 0
B22: Airport Parking | C22: Per traveler | D22: 0 | G22: 0 | J22: 0 | M22: 0
B23: Shipping (to) | C23: Trip-level | D23: 0 | G23: 0 | J23: 0 | M23: 0
B24: Shipping (back) | C24: Trip-level | D24: 0 | G24: 0 | J24: 0 | M24: 0
... B30: Mileage (Personal Vehicle) | C30: Trip-level | D30: 0 | G30: 0 | J30: 0 | M30: 0
B31: Entered by the SUPERVISOR at review (not on the submit form)
B32: Traveler 1 EWW Rate (per hour) | C32: Supervisor review > EWW Rate | D32: 0 | G32: 0 | J32: 0 | M32: 0
B33: Traveler 1 EWW Hours | D33: 0 | G33: 0 | J33: 0 | M33: 0
B34: Traveler 2 EWW Rate (per hour) | D34: 0 | G34: 0 | J34: 0 | M34: 0
B35: Traveler 2 EWW Hours | D35: 0 | G35: 0 | J35: 0 | M35: 0
B36: Traveler 3 EWW Rate (per hour) | D36: 0 | G36: 0 | J36: 0 | M36: 0
B37: Traveler 3 EWW Hours | D37: 0 | G37: 0 | J37: 0 | M37: 0
B38: Traveler 4 EWW Rate (per hour) | D38: 0 | G38: 0 | J38: 0 | M38: 0
B39: Traveler 4 EWW Hours | D39: 0 | G39: 0 | J39: 0 | M39: 0
B40: EWW already saved when submitted? (1 = yes) | C40: Only a resubmission after a Supervisor return carries EWW | D40: 0 | G40: 0 | J40: 0 | M40: 0
A42: 2. EXPECTED MATH — live formulas (read these to follow the arithmetic)
A43: Ref | B43: Field / what to read | C43: Screen label / how it is calculated | D43: S7a | G43: S7b | J43: S7c-1 | M43: S7c-2
B44: Nights | C44: Return Date - Leave Date (never below 0) | D44: =MAX(0,D12-D11) -> 2 | G44: =MAX(0,G12-G11) -> 2 | J44: =MAX(0,J12-J11) -> 2 | M44: =MAX(0,M12-M11) -> 2
B45: Full Days (1x) | C45: Nights - 1, minimum 0 | D45: =MAX(D44-1,0) -> 1 | G45: =MAX(G44-1,0) -> 1 | J45: =MAX(J44-1,0) -> 1 | M45: =MAX(M44-1,0) -> 1
B46: Per Diem Meals Total (per traveler) | C46: 1.5 x M&IE + Full Days x M&IE | D46: =1.5*D15+D45*D15 -> 147.5 | G46: =1.5*G15+G45*G15 -> 147.5 | J46: =1.5*J15+J45*J15 -> 147.5 | M46: =1.5*M15+M45*M15 -> 147.5
B47: Per-traveler costs (excl. meals) | C47: Total Lodging + Airfare + Airport Parking + Baggage | D47: =D17+D20+D22+D21 -> 548.64 | G47: =G17+G20+G22+G21 -> 574.64 | J47: =J17+J20+J22+J21 -> 524.64 | M47: =M17+M20+M22+M21 -> 538.64
...

Sheet S8
A1: S8 — Expense return and resubmit, expense deny
A2: The expense-side rejection paths. Two minimal authorized estimates: S8a's expense report is returned, corrected and resubmitted, then approved; S8b's is denied and stored read-only.
A3: Travel type: Fly, 1 traveler (light data) | Expected emails: 19 | Fee multiplier from Setup tab
A5: 1. INPUTS — type these exactly (blue)
A6: Ref | B6: Field / what to read | C6: Screen label / how it is calculated | D6: S8a | G6: S8b
B7: Event Name | C7: Add your initials at the end | D7: S8a Expense Return - xx | G7: S8b Expense Deny - xx
B8: City | D8: Phoenix | G8: Tucson
B9: State | C9: Pick from the list | D9: AZ | G9: AZ
B10: Contract | C10: Pick any contract; note which one | D10: (any) | G10: (any)
B11: Leave Date | D11: 46365 | G11: 46365
B12: Return Date | D12: 46367 | G12: 46367
B13: Travelers | C13: Traveler 2-4: pick any roster employee | D13: 1 | G13: 1
B14: GSA Lodging Rate (per night) | C14: Overwrite AFTER the lookup finishes | D14: 125 | G14: 125
B15: Meals (M&IE) Rate (per day) | C15: Overwrite AFTER the lookup finishes | D15: 61 | G15: 61
B16: Room Cost (subject to per diem limit) | C16: Per traveler, whole stay | D16: 236 | G16: 236
B17: Total Lodging Cost (incl. taxes & fees) | C17: Per traveler, whole stay | D17: 261.96 | G17: 261.96
B18: Lodging Fees | C18: Recorded only | D18: 0 | G18: 0
B19: Lodging Taxes | C19: Recorded only | D19: 25.96 | G19: 25.96
B20: Airfare (avg) | C20: Per traveler | D20: 280 | G20: 305
B21: Baggage | C21: Per traveler | D21: 0 | G21: 0
B22: Airport Parking | C22: Per traveler | D22: 0 | G22: 0
B23: Shipping (to) | C23: Trip-level | D23: 0 | G23: 0
B24: Shipping (back) | C24: Trip-level | D24: 0 | G24: 0
... B30: Mileage (Personal Vehicle) | C30: Trip-level | D30: 0 | G30: 0
B31: Entered by the SUPERVISOR at review (not on the submit form)
B32: Traveler 1 EWW Rate (per hour) | C32: Supervisor review > EWW Rate | D32: 0 | G32: 0
B33: Traveler 1 EWW Hours | D33: 0 | G33: 0
B34: Traveler 2 EWW Rate (per hour) | D34: 0 | G34: 0
B35: Traveler 2 EWW Hours | D35: 0 | G35: 0
B36: Traveler 3 EWW Rate (per hour) | D36: 0 | G36: 0
B37: Traveler 3 EWW Hours | D37: 0 | G37: 0
B38: Traveler 4 EWW Rate (per hour) | D38: 0 | G38: 0
B39: Traveler 4 EWW Hours | D39: 0 | G39: 0
B40: EWW already saved when submitted? (1 = yes) | C40: Only a resubmission after a Supervisor return carries EWW | D40: 0 | G40: 0
A42: 2. EXPECTED MATH — live formulas (read these to follow the arithmetic)
A43: Ref | B43: Field / what to read | C43: Screen label / how it is calculated | D43: S8a | G43: S8b
B44: Nights | C44: Return Date - Leave Date (never below 0) | D44: =MAX(0,D12-D11) -> 2 | G44: =MAX(0,G12-G11) -> 2
B45: Full Days (1x) | C45: Nights - 1, minimum 0 | D45: =MAX(D44-1,0) -> 1 | G45: =MAX(G44-1,0) -> 1
B46: Per Diem Meals Total (per traveler) | C46: 1.5 x M&IE + Full Days x M&IE | D46: =1.5*D15+D45*D15 -> 152.5 | G46: =1.5*G15+G45*G15 -> 152.5
B47: Per-traveler costs (excl. meals) | C47: Total Lodging + Airfare + Airport Parking + Baggage | D47: =D17+D20+D22+D21 -> 541.96 | G47: =G17+G20+G22+G21 -> 566.96
...

Sheet Emails
A1: Email log — expected vs received
A2: All emails land in the one signed-in inbox. Log each as it arrives. Short notices carry no trip name, so match them by the time of your action.
A4: Scenario | B4: Expected | C4: Received | D4: Unexpected extras (you) | E4: Status
A5: S1 | B5: =COUNTIF($B$17:$B$102,A5) -> 8 | C5: =COUNTIFS($B$17:$B$102,A5,$L$17:$L$102,"Y") -> 0 | E5: =IF(C5=0,"",IF(AND(C5=B5,D5=0),"OK","CHECK"))
A6: S2 | B6: =COUNTIF($B$17:$B$102,A6) -> 8 | C6: =COUNTIFS($B$17:$B$102,A6,$L$17:$L$102,"Y") -> 0 | E6: =IF(C6=0,"",IF(AND(C6=B6,D6=0),"OK","CHECK"))
A7: S3 | B7: =COUNTIF($B$17:$B$102,A7) -> 9 | C7: =COUNTIFS($B$17:$B$102,A7,$L$17:$L$102,"Y") -> 0 | E7: =IF(C7=0,"",IF(AND(C7=B7,D7=0),"OK","CHECK"))
A8: S4 | B8: =COUNTIF($B$17:$B$102,A8) -> 8 | C8: =COUNTIFS($B$17:$B$102,A8,$L$17:$L$102,"Y") -> 0 | E8: =IF(C8=0,"",IF(AND(C8=B8,D8=0),"OK","CHECK"))
A9: S5 | B9: =COUNTIF($B$17:$B$102,A9) -> 9 | C9: =COUNTIFS($B$17:$B$102,A9,$L$17:$L$102,"Y") -> 0 | E9: =IF(C9=0,"",IF(AND(C9=B9,D9=0),"OK","CHECK"))
A10: S6 | B10: =COUNTIF($B$17:$B$102,A10) -> 8 | C10: =COUNTIFS($B$17:$B$102,A10,$L$17:$L$102,"Y") -> 0 | E10: =IF(C10=0,"",IF(AND(C10=B10,D10=0),"OK","CHECK"))
A11: S7 | B11: =COUNTIF($B$17:$B$102,A11) -> 17 | C11: =COUNTIFS($B$17:$B$102,A11,$L$17:$L$102,"Y") -> 0 | E11: =IF(C11=0,"",IF(AND(C11=B11,D11=0),"OK","CHECK"))
A12: S8 | B12: =COUNTIF($B$17:$B$102,A12) -> 19 | C12: =COUNTIFS($B$17:$B$102,A12,$L$17:$L$102,"Y") -> 0 | E12: =IF(C12=0,"",IF(AND(C12=B12,D12=0),"OK","CHECK"))
A13: Total | B13: =SUM(B5:B12) -> 86 | C13: =SUM(C5:C12) -> 0 | D13: =SUM(D5:D12) -> 0
A14: Note: expense-report actions are expected to send NO email (Watch W3). Count any that arrive as "Unexpected extras".
A16: Email ID | B16: Scenario | C16: Step | D16: Estimate | E16: Expected subject | F16: Template | G16: Check 1 | H16: Expected 1 | I16: Check 2 | J16: Expected 2 | K16: Also verify | L16: Received? Y/N | M16: Time received | N16: Subject OK? Y/N | O16: Figures OK? Y/N | P16: Tracking # seen | Q16: Notes
A17: S1-E1 | B17: S1 | C17: 6 | D17: S1 | E17: Travel estimate submitted — Columbia, SC | F17: Submitter copy (Requested column only) | G17: Trip Lead Total | H17: ='S1'!D50 -> 894.7 | I17: Grand Total | J17: ='S1'!D75 -> 894.7 | K17: Heading "Columbia, SC — S1 Regional Workshop", 3 nights. Requested column only; no Billable column. No Tracking # yet (none is issued until the first approval). EWW table lists 1 traveler(s) at $0.00.
A18: S1-E2 | B18: S1 | C18: 6 | D18: S1 | E18: Action needed: review as Supervisor — Columbia, SC | F18: Supervisor nudge (same body as submitter copy) | G18: Trip Lead Total | H18: ='S1'!D50 -> 894.7 | I18: Grand Total | J18: ='S1'!D75 -> 894.7 | K18: Heading "Columbia, SC — S1 Regional Workshop", 3 nights. Requested column only; no Billable column. No Tracking # yet (none is issued until the first approval). EWW table lists 1 traveler(s) at $0.00.
A19: S1-E3 | B19: S1 | C19: 9 | D19: S1 | E19: Travel estimate approved — Columbia, SC — <Tracking #> | F19: Supervisor record (Requested + Billable to Prime columns) | G19: Billable to Prime (ODC) | H19: ='S1'!D72 -> 978.37 | I19: Grand Total to Prime | J19: ='S1'!D73 -> 978.37 | K19: Tracking # (SLIN code, hyphen, 5 digits) in the subject and the body. SLIN code in the heading. Requested AND Billable to Prime columns. Totals rows: Trip Lead, EWW, Grand, Billable to Prime (ODC), Grand Total to Prime. Check EWW table.
A20: S1-E4 | B20: S1 | C20: 9 | D20: S1 | E20: Action needed: Prime authorization — Columbia, SC — <Tracking #> | F20: Prime copy (single marked-up Total column) | G20: Trip Lead Total (marked up) | H20: ='S1'!D72 -> 978.37 | I20: Grand Total (marked up) | J20: ='S1'!D73 -> 978.37 | K20: Tracking # (SLIN code, hyphen, 5 digits) in the subject and the body. Single "Total" column (marked up). Must NOT contain: Requested, Billable to Prime, the Fees/Taxes note, internal Trip Lead.
A21: S1-E5 | B21: S1 | C21: 11 | D21: S1 | E21: Travel authorized — Columbia, SC — <Tracking #> | F21: Notice: Prime authorized the trip | K21: Short notice that names the trip and carries the Tracking # in the subject and the body.
A22: S1-E6 | B22: S1 | C22: 17 | D22: S1 | E22: Expense report submitted — Columbia, SC — <Tracking #> | F22: Expense submitter copy (actual vs estimated) | G22: Actual Grand Total | H22: ='S1'!D144 -> 896 | I22: Variance vs. Estimate | J22: ='S1'!D146 -> 1.3 | K22: Tracking # (SLIN code, hyphen, 5 digits) in the subject and the body. It must be the SAME number as the estimate. Heading shows actual dates and travelers. Table of Estimated / Actual / Difference per category; Explanations section lists the variance and added-category notes; Totals include the read-only EWW Total.
A23: S1-E7 | B23: S1 | C23: 17 | D23: S1 | E23: Action needed: review expense report as Supervisor — Columbia, SC — <Tracking #> | F23: Expense Supervisor nudge (same body) | G23: Actual Grand Total | H23: ='S1'!D144 -> 896 | I23: Variance vs. Estimate | J23: ='S1'!D146 -> 1.3 | K23: Tracking # (SLIN code, hyphen, 5 digits) in the subject and the body. It must be the SAME number as the estimate. Heading shows actual dates and travelers. Table of Estimated / Actual / Difference per category; Explanations section lists the variance and added-category notes; Totals include the read-only EWW Total.
A24: S1-E8 | B24: S1 | C24: 19 | D24: S1 | E24: Expense report approved — Columbia, SC — <Tracking #> | F24: Expense approved (reimbursement finalized) | G24: Actual Grand Total | H24: ='S1'!D144 -> 896 | I24: Variance vs. Estimate | J24: ='S1'!D146 -> 1.3 | K24: Tracking # (SLIN code, hyphen, 5 digits) in the subject and the body. It must be the SAME number as the estimate. Heading shows actual dates and travelers. Table of Estimated / Actual / Difference per category; Explanations section lists the variance and added-category notes; Totals include the read-only EWW Total.
A25: S2-E1 | B25: S2 | C25: 4 | D25: S2 | E25: Travel estimate submitted — Austin, TX | F25: Submitter copy (Requested column only) | G25: Trip Lead Total | H25: ='S2'!D50 -> 2890.1 | I25: Grand Total | J25: ='S2'!D75 -> 2890.1 | K25: Heading "Austin, TX — S2 Customer Site Visit", 3 nights. Requested column only; no Billable column. No Tracking # yet (none is issued until the first approval). EWW table lists 2 traveler(s) at $0.00.
A26: S2-E2 | B26: S2 | C26: 4 | D26: S2 | E26: Action needed: review as Supervisor — Austin, TX | F26: Supervisor nudge (same body as submitter copy) | G26: Trip Lead Total | H26: ='S2'!D50 -> 2890.1 | I26: Grand Total | J26: ='S2'!D75 -> 2890.1 | K26: Heading "Austin, TX — S2 Customer Site Visit", 3 nights. Requested column only; no Billable column. No Tracking # yet (none is issued until the first approval). EWW table lists 2 traveler(s) at $0.00.
A27: S2-E3 | B27: S2 | C27: 7 | D27: S2 | E27: Travel estimate approved — Austin, TX — <Tracking #> | F27: Supervisor record (Requested + Billable to Prime columns) | G27: Billable to Prime (ODC) | H27: ='S2'!D72 -> 3192.31 | I27: Grand Total to Prime | J27: ='S2'!D73 -> 3942.31 | K27: Tracking # (SLIN code, hyphen, 5 digits) in the subject and the body. SLIN code in the heading. Requested AND Billable to Prime columns. Totals rows: Trip Lead, EWW, Grand, Billable to Prime (ODC), Grand Total to Prime. Check EWW table.
A28: S2-E4 | B28: S2 | C28: 7 | D28: S2 | E28: Action needed: Prime authorization — Austin, TX — <Tracking #> | F28: Prime copy (single marked-up Total column) | G28: Trip Lead Total (marked up) | H28: ='S2'!D72 -> 3192.31 | I28: Grand Total (marked up) | J28: ='S2'!D73 -> 3942.31 | K28: Tracking # (SLIN code, hyphen, 5 digits) in the subject and the body. Single "Total" column (marked up). Must NOT contain: Requested, Billable to Prime, the Fees/Taxes note, internal Trip Lead.
A29: S2-E5 | B29: S2 | C29: 8 | D29: S2 | E29: Travel authorized — Austin, TX — <Tracking #> | F29: Notice: Prime authorized the trip | K29: Short notice that names the trip and carries the Tracking # in the subject and the body.
A30: S2-E6 | B30: S2 | C30: 15 | D30: S2 | E30: Expense report submitted — Austin, TX — <Tracking #> | F30: Expense submitter copy (actual vs estimated) | G30: Actual Grand Total | H30: ='S2'!D154 -> 3978.5 | I30: Variance vs. Estimate | J30: ='S2'!D156 -> 338.4 | K30: Tracking # (SLIN code, hyphen, 5 digits) in the subject and the body. It must be the SAME number as the estimate. Heading shows actual dates and travelers. Table of Estimated / Actual / Difference per category; Explanations section lists the variance and added-category notes; Totals include the read-only EWW Total.
A31: S2-E7 | B31: S2 | C31: 15 | D31: S2 | E31: Action needed: review expense report as Supervisor — Austin, TX — <Tracking #> | F31: Expense Supervisor nudge (same body) | G31: Actual Grand Total | H31: ='S2'!D154 -> 3978.5 | I31: Variance vs. Estimate | J31: ='S2'!D156 -> 338.4 | K31: Tracking # (SLIN code, hyphen, 5 digits) in the subject and the body. It must be the SAME number as the estimate. Heading shows actual dates and travelers. Table of Estimated / Actual / Difference per category; Explanations section lists the variance and added-category notes; Totals include the read-only EWW Total.
A32: S2-E8 | B32: S2 | C32: 17 | D32: S2 | E32: Expense report approved — Austin, TX — <Tracking #> | F32: Expense approved (reimbursement finalized) | G32: Actual Grand Total | H32: ='S2'!D154 -> 3978.5 | I32: Variance vs. Estimate | J32: ='S2'!D156 -> 338.4 | K32: Tracking # (SLIN code, hyphen, 5 digits) in the subject and the body. It must be the SAME number as the estimate. Heading shows actual dates and travelers. Table of Estimated / Actual / Difference per category; Explanations section lists the variance and added-category notes; Totals include the read-only EWW Total.
A33: S3-E1 | B33: S3 | C33: 3 | D33: S3a | E33: Travel estimate submitted — Nashville, TN | F33: Submitter copy (Requested column only) | G33: Trip Lead Total | H33: ='S3'!D53 -> 1202 | I33: Grand Total | J33: ='S3'!D78 -> 1202 | K33: Heading "Nashville, TN — S3a Fees-Taxes Excluded", 3 nights. Requested column only; no Billable column. No Tracking # yet (none is issued until the first approval). EWW table lists 1 traveler(s) at $0.00.
A34: S3-E2 | B34: S3 | C34: 3 | D34: S3a | E34: Action needed: review as Supervisor — Nashville, TN | F34: Supervisor nudge (same body as submitter copy) | G34: Trip Lead Total | H34: ='S3'!D53 -> 1202 | I34: Grand Total | J34: ='S3'!D78 -> 1202 | K34: Heading "Nashville, TN — S3a Fees-Taxes Excluded", 3 nights. Requested column only; no Billable column. No Tracking # yet (none is issued until the first approval). EWW table lists 1 traveler(s) at $0.00.
A35: S3-E3 | B35: S3 | C35: 4 | D35: S3a | E35: Travel estimate approved — Nashville, TN — <Tracking #> | F35: Supervisor record (Requested + Billable to Prime columns) | G35: Billable to Prime (ODC) | H35: ='S3'!D75 -> 1324.38 | I35: Grand Total to Prime | J35: ='S3'!D76 -> 1324.38 | K35: Tracking # (SLIN code, hyphen, 5 digits) in the subject and the body. SLIN code in the heading. Requested AND Billable to Prime columns. Totals rows: Trip Lead, EWW, Grand, Billable to Prime (ODC), Grand Total to Prime. Check EWW table.
A36: S3-E4 | B36: S3 | C36: 4 | D36: S3a | E36: Action needed: Prime authorization — Nashville, TN — <Tracking #> | F36: Prime copy (single marked-up Total column) | G36: Trip Lead Total (marked up) | H36: ='S3'!D75 -> 1324.38 | I36: Grand Total (marked up) | J36: ='S3'!D76 -> 1324.38 | K36: Tracking # (SLIN code, hyphen, 5 digits) in the subject and the body. Single "Total" column (marked up). Must NOT contain: Requested, Billable to Prime, the Fees/Taxes note, internal Trip Lead.
A37: S3-E5 | B37: S3 | C37: 10 | D37: S3b | E37: Travel estimate submitted — Memphis, TN | F37: Submitter copy (Requested column only) | G37: Trip Lead Total | H37: ='S3'!G53 -> 1275.05 | I37: Grand Total | J37: ='S3'!G78 -> 1275.05 | K37: Heading "Memphis, TN — S3b Over Limit With Quotes", 3 nights. Requested column only; no Billable column. No Tracking # yet (none is issued until the first approval). EWW table lists 1 traveler(s) at $0.00.
A38: S3-E6 | B38: S3 | C38: 10 | D38: S3b | E38: Action needed: review as Supervisor — Memphis, TN | F38: Supervisor nudge (same body as submitter copy) | G38: Trip Lead Total | H38: ='S3'!G53 -> 1275.05 | I38: Grand Total | J38: ='S3'!G78 -> 1275.05 | K38: Heading "Memphis, TN — S3b Over Limit With Quotes", 3 nights. Requested column only; no Billable column. No Tracking # yet (none is issued until the first approval). EWW table lists 1 traveler(s) at $0.00.
A39: S3-E7 | B39: S3 | C39: 12 | D39: S3b | E39: Travel estimate approved — Memphis, TN — <Tracking #> | F39: Supervisor record (Requested + Billable to Prime columns) | G39: Billable to Prime (ODC) | H39: ='S3'!G75 -> 1406.73 | I39: Grand Total to Prime | J39: ='S3'!G76 -> 1666.73 | K39: Tracking # (SLIN code, hyphen, 5 digits) in the subject and the body. SLIN code in the heading. Requested AND Billable to Prime columns. Totals rows: Trip Lead, EWW, Grand, Billable to Prime (ODC), Grand Total to Prime. Check EWW table.
A40: S3-E8 | B40: S3 | C40: 12 | D40: S3b | E40: Action needed: Prime authorization — Memphis, TN — <Tracking #> | F40: Prime copy (single marked-up Total column) | G40: Trip Lead Total (marked up) | H40: ='S3'!G75 -> 1406.73 | I40: Grand Total (marked up) | J40: ='S3'!G76 -> 1666.73 | K40: Tracking # (SLIN code, hyphen, 5 digits) in the subject and the body. Single "Total" column (marked up). Must NOT contain: Requested, Billable to Prime, the Fees/Taxes note, internal Trip Lead.
A41: S3-E9 | B41: S3 | C41: 13 | D41: S3b | E41: Travel authorized — Memphis, TN — <Tracking #> | F41: Notice: Prime authorized the trip | K41: Short notice that names the trip and carries the Tracking # in the subject and the body.
A42: S4-E1 | B42: S4 | C42: 4 | D42: S4 | E42: Travel estimate submitted — San Diego, CA | F42: Submitter copy (Requested column only) | G42: Trip Lead Total | H42: ='S4'!D50 -> 15062.48 | I42: Grand Total | J42: ='S4'!D75 -> 15062.48 | K42: Heading "San Diego, CA — S4 Training Cohort Onsite", 10 nights. Requested column only; no Billable column. No Tracking # yet (none is issued until the first approval). EWW table lists 4 traveler(s) at $0.00.
...

Sheet Controls
A1: Control coverage matrix
A2: A dot means a step in that scenario uses the control. Built from the Steps tab, so it always matches what you actually run.
C3: Controls total / covered / gaps | D3: =COUNTA(A6:A92)&" controls | "&COUNTIF(N6:N92,"Covered")&" covered | "&COUNTIF(N6:N92,"GAP")&" gaps" -> 87 controls | 87 covered | 0 gaps
A5: ID | B5: Area | C5: Control | D5: What to verify | E5: S1 | F5: S2 | G5: S3 | H5: S4 | I5: S5 | J5: S6 | K5: S7 | L5: S8 | M5: Scenarios | N5: Status
